Workbook

Sheet README
A1: Chapter 29 — Deployment Patterns and Economics
A2: Companion workbook of The Birth and Adolescence of Artificial Intelligence, Volume 2, by Leonhard Korowajczuk. Blue cells on a light yellow background are inputs: change them and every result recalculates.
A4: Sheet | B4: What it computes | C4: Book reference
A5: Token Cost | B5: Blended API prices for an 8:1 workload, cached and batch prices, and the cost per million tokens of rented or owned GPUs at two utilizations. | C5: Section 29.2, Table 29.1, Worked Example 29.1
A6: Owned TCO | B6: Hourly cost of an owned eight-GPU H200 server: depreciation, electricity or colocation, maintenance and staff; utilization and cost of capital. | C6: Section 29.3, Worked Example 29.2, Figure 29.2
A7: Break-even | B7: A 2,000-user assistant on frontier, managed and owned options; the break-even volumes of Section 29.4; the Box per person. | C7: Section 29.4, Worked Example 29.3, Figure 29.3
A8: Availability | B8: Downtime allowed by an SLA and the floor reached by two independent providers with failover. | C8: Section 29.6, Worked Example 29.4
A10: Notes
A11: Prices are US list or published prices as of October 2026 (Table 29.1), before taxes, network, storage and the cost of capital unless stated.
A12: Throughput (8,000 tokens/s per H200, 2,700 per RTX PRO 6000 Server Edition) is an estimate from published benchmarks: replace it with the measured goodput of Section 16.6.
A13: A month is 730 hours; a year 8,760 hours.

Sheet Token Cost
A1: What a Million Tokens of gpt-oss-120b Costs, Four Ways (Worked Example 29.1)
A3: Workload and API prices (Table 29.1) | B3: Value
A4: Input tokens per output token | B4: 8
A5: Output tokens (per the ratio above) | B5: 1
A6: Managed gpt-oss-120b, input (US$ per million tokens) | B6: 0.15
A7: Managed gpt-oss-120b, output (US$ per million tokens) | B7: 0.6
A8: Cheapest managed gpt-oss-120b (DeepInfra), input (US$/M) | B8: 0.037
A9: Cheapest managed gpt-oss-120b (DeepInfra), output (US$/M) | B9: 0.17
A10: Frontier API, mid tier, input (US$/M) | B10: 2
A11: Frontier API, mid tier, output (US$/M) | B11: 10
A12: Frontier API, low tier, input (US$/M) | B12: 0.1
A13: Frontier API, low tier, output (US$/M) | B13: 0.5
A15: Hardware | B15: Value
A16: Throughput of one H200 serving gpt-oss-120b (tokens/s, input + output) | B16: 8000
A17: Alternative, production throughput (tokens/s) | B17: 4000
A18: AWS p5en on demand, 8 × H200 (US$ per hour) | B18: 63.3
A19: GPUs in the AWS instance | B19: 8
A20: Neocloud H200 on demand, mid-range (US$ per GPU-hour) | B20: 4.5
A21: Neocloud H200 on demand, lowest listed (US$ per GPU-hour) | B21: 2.69
A22: Utilization, case 1 | B22: 1
A23: Utilization, case 2 | B23: 0.5
A24: SemiAnalysis ownership cost at hyperscale, H200 (US$ per GPU-hour) | B24: 1.22
A25: SemiAnalysis cost per million tokens, low (US$) | B25: 0.03
A26: SemiAnalysis cost per million tokens, high (US$) | B26: 0.05
A28: Discounts (Section 29.2) | B28: Value
A29: Input tokens per request | B29: 8000
A30: Output tokens per request | B30: 1000
A31: Shared prefix billed as cached input (tokens) | B31: 2000
A32: Cached input price ÷ input price (Table 22.2) | B32: 0.1
A33: Batch price ÷ list price (Table 27.4) | B33: 0.5
A35: Blended prices (US$ per million tokens) | B35: Workbook | C35: Value in the book
A36: Managed gpt-oss-120b | B36: =(B4*B6+B5*B7)/(B4+B5) -> 0.2 | C36: 0.20
A37: Frontier, mid tier | B37: =(B4*B10+B5*B11)/(B4+B5) -> 2.8888889 | C37: 2.89
A38: Frontier, low tier | B38: =(B4*B12+B5*B13)/(B4+B5) -> 0.14444444 | C38: 0.14
A39: Cheapest managed gpt-oss-120b | B39: =(B4*B8+B5*B9)/(B4+B5) -> 0.051777778 | C39: about 0.05
A40: Frontier, mid tier, with the shared prefix cached | B40: =((B29-B31)*B10+B31*B10*B32+B30*B11)/(B29+B30) -> 2.4888889 | C40: 2.49
A41: Frontier, mid tier, batch interface | B41: =B37*B33 -> 1.4444444 | C41: 1.44
A43: Hardware (US$ per million tokens) | B43: Workbook | C43: Value in the book
A44: Tokens per GPU-hour (millions) | B44: =B16*3600/10^6 -> 28.8 | C44: 28.8
A45: AWS price per GPU-hour (US$) | B45: =B18/B19 -> 7.9125 | C45: 7.91
...

Sheet Owned TCO
A1: The Hourly Cost of an Owned Eight-GPU H200 Server (Worked Example 29.2)
A3: Inputs | B3: Value
A4: Purchase price (US$; Table 29.1) | B4: 320000
A5: GPUs in the server | B5: 8
A6: IT load at full use (kW) | B6: 10
A7: PUE (Uptime Institute 2025 average) | B7: 1.54
A8: Electricity (US$ per kWh; EIA, July 2026) | B8: 0.1453
A9: Maintenance and support (share of the purchase price per year) | B9: 0.1
A10: Engineers per server | B10: 0.25
A11: Loaded cost of an engineer (US$ per year) | B11: 180000
A12: Depreciation life, short case (years) | B12: 3
A13: Depreciation life, long case (years) | B13: 5
A14: Hours per year | B14: 8760
A15: Hours per month | B15: 730
... A20: Cost of capital (per year) | B20: 0.08
A21: AWS on demand (US$ per GPU-hour; Token Cost sheet) | B21: ='Token Cost'!B45 -> 7.9125
A22: Neocloud, mid-range (US$ per GPU-hour; Token Cost sheet) | B22: ='Token Cost'!B20 -> 4.5
A24: Hourly cost of the server (US$ per hour) | B24: Workbook | C24: Value in the book
A25: Depreciation, short life | B25: =B4/(B12*B14) -> 12.17656 | C25: 12.18
A26: Depreciation, long life | B26: =B4/(B13*B14) -> 7.3059361 | C26: 7.31
A27: Electricity | B27: =B6*B7*B8 -> 2.23762 | C27: 2.24
A28: Maintenance | B28: =B4*B9/B14 -> 3.652968 | C28: 3.65
A29: Staff | B29: =B10*B11/B14 -> 5.1369863 | C29: 5.14
A30: Total, short life | B30: =B25+B27+B28+B29 -> 23.204134 | C30: 23.21
A31: Total, long life | B31: =B26+B27+B28+B29 -> 18.33351 | C31: 18.34
A32: Per GPU-hour, short life | B32: =B30/B5 -> 2.9005168 | C32: 2.90
A33: Per GPU-hour, long life | B33: =B31/B5 -> 2.2916888 | C33: 2.29
A34: Per month, short life (US$) | B34: =B30*B15 -> 16939.018 | C34: about 16,900
A36: Utilization (US$ per busy GPU-hour, short life) | B36: Workbook | C36: Value in the book
A37: At utilization A | B37: =B32/B16 -> 5.8010336 | C37: 5.80
A38: At utilization B | B38: =B32/B17 -> 11.602067 | C38: 11.60
A39: Utilization B costs more than AWS on demand? | B39: =IF(B38>B21,"yes","no") -> yes | C39: yes
A40: Utilization at which owned equals AWS on demand | B40: =B32/B21 -> 0.366574 | C40: about 40% (Section 29.8)
A41: Utilization at which owned equals the mid-range neocloud | B41: =B32/B22 -> 0.64455929 | C41: about 65%
A43: Variants and shares | B43: Workbook | C43: Value in the book
A44: Colocation: space and cooling (US$ per hour) | B44: =B18*B6/B15 -> 2.6849315 | C44: about 2.70
A45: Colocation: IT power billed on top (US$ per hour) | B45: =B6*B8 -> 1.453 | C45: about 1.45
A46: Colocation: total, short life (US$ per hour) | B46: =B25+B44+B45+B28+B29 -> 25.104446 | C46: about 25.10
A47: Colocation: per GPU-hour, short life | B47: =B46/B5 -> 3.1380557 | C47: 3.14
A48: At the alternative price: per GPU-hour, short life | B48: =(B19/(B12*B14)+B27+B19*B9/B14+B29)/B5 -> 3.3951896 | C48: about 3.40
...

Sheet Break-even
A1: A Corporate Assistant for 2,000 Engineers (Worked Example 29.3)
A3: Workload | B3: Value
A4: Staff | B4: 2000
A5: Requests per person per working day | B5: 40
A6: Working days per month | B6: 22
A7: Input tokens per request | B7: 8000
A8: Output tokens per request | B8: 1000
A9: Working hours per day (Figure 30.3) | B9: 10
A10: Share of the day's tokens in the busiest hour (Worked Example 30.3) | B10: 0.14
A11: Hybrid: share of requests sent to the mid-tier API | B11: 0.1
A13: Owned hardware | B13: Value
A14: H200 node: GPUs | B14: 8
A15: Entry node, 8 × RTX PRO 6000 Server Edition: price (US$; Table A.1) | B15: 250000
A16: Entry node: power (kW; Worked Example 15.3) | B16: 6.3
A17: Entry node: GPUs | B17: 8
A18: Entry node: throughput per GPU (tokens/s; Worked Example 30.3) | B18: 2700
A19: Planning limit at the busiest hour (Section 30.6) | B19: 0.7
A20: CPU nodes, storage and network (US$ per month; Worked Example 35.3) | B20: 6000
A22: Volume | B22: Workbook | C22: Value in the book
A23: Tokens per month (billions) | B23: =B4*B5*B6*(B7+B8)/10^9 -> 15.84 | C23: 15.8
A24: Input tokens per month (billions) | B24: =B4*B5*B6*B7/10^9 -> 14.08 | C24: 14.1
A25: Output tokens per month (billions) | B25: =B4*B5*B6*B8/10^9 -> 1.76 | C25: 1.76
A26: Average over the working hours (tokens/s) | B26: =B23*10^9/(B6*B9*3600) -> 20000 | C26: about 20,000
A27: Busiest hour (tokens/s) | B27: =B23*10^9/B6*B10/3600 -> 28000 | C27: about 28,000
A29: All on an API (US$ per month) | B29: Workbook | C29: Value in the book
A30: Mid-tier frontier API | B30: =B24*1000*'Token Cost'!B10+B25*1000*'Token Cost'!B11 -> 45760 | C30: 45,800
A31: per person | B31: =B30/B4 -> 22.88 | C31: 22.90
A32: Managed gpt-oss-120b | B32: =B24*1000*'Token Cost'!B6+B25*1000*'Token Cost'!B7 -> 3168 | C32: 3,200
A33: Managed gpt-oss-120b, cheapest provider | B33: =B24*1000*'Token Cost'!B8+B25*1000*'Token Cost'!B9 -> 820.16 | C33: under 1,000
A34: Low-tier frontier API | B34: =B24*1000*'Token Cost'!B12+B25*1000*'Token Cost'!B13 -> 2288 | C34: 2,300
A36: On an owned 8 × H200 node | B36: Workbook | C36: Value in the book
A37: Cost per month (US$; Owned TCO sheet) | B37: ='Owned TCO'!B34 -> 16939.018 | C37: 16,900
A38: Capacity at 100% (billion tokens per month) | B38: =B14*'Token Cost'!B16*3600*'Owned TCO'!B15/10^9 -> 168.192 | C38: 168
A39: Utilization averaged over the month | B39: =B23/B38 -> 0.094178082 | C39: 9%
A40: Utilization during working hours | B40: =B26/(B14*'Token Cost'!B16) -> 0.3125 | C40: about 30%
A42: On owned entry nodes (US$ per hour per node unless stated) | B42: Workbook | C42: Value in the book
A43: Depreciation | B43: =B15/('Owned TCO'!B12*'Owned TCO'!B14) -> 9.5129376 | C43: 9.51
A44: Electricity | B44: =B16*'Owned TCO'!B7*'Owned TCO'!B8 -> 1.4097006 | C44: 1.41
A45: Maintenance | B45: =B15*'Owned TCO'!B9/'Owned TCO'!B14 -> 2.8538813 | C45: 2.85
A46: Staff | B46: ='Owned TCO'!B29 -> 5.1369863 | C46: 5.14
...

Sheet Availability
A1: How Much Downtime an SLA Allows, and What a Fallback Buys (Worked Example 29.4)
A3: Inputs | B3: Value
A4: SLA of one provider, case 1 | B4: 0.999
A5: SLA of one provider, case 2 | B5: 0.995
A6: Provider 1 availability (failover pair) | B6: 0.995
A7: Provider 2 availability (failover pair) | B7: 0.995
A8: Hours per month | B8: 730
A10: Results | B10: Workbook | C10: Value in the book
A11: Permitted downtime at SLA case 1 (hours per month) | B11: =(1-B4)*B8 -> 0.73 | C11: 0.73
A12: in minutes | B12: =B11*60 -> 43.8 | C12: ≈ 44
A13: Permitted downtime at SLA case 2 (hours per month) | B13: =(1-B5)*B8 -> 3.65 | C13: 3.65
A14: Unavailability of the failover pair (both down) | B14: =(1-B6)*(1-B7) -> 2.5e-05 | C14: 0.0025%
A15: in minutes per month | B15: =B14*B8*60 -> 1.095 | C15: ≈ 1.1
A16: Availability of the failover pair | B16: =1-B14 -> 0.999975
A18: A theoretical floor: it assumes independent failures and instant failover. SLA percentages are thresholds for service credits, not predictions; providers in the same region or behind the same gateway fail together.
A19: Reading: independence must be engineered — different providers, regions and network paths — and a local Box or Rack model removes the dependency for data that never leaves the premises.
